<?xml version="1.0" ?>
<robot name="armpi_ultra" xmlns:xacro="http://ros.org/wiki/xacro"> 

  <link name="base_link">
    <inertial>
      <origin rpy="0 0 0" xyz="0.0164042229877272 -2.04513182262022E-05 0.0219693028117164"/>
      <mass value="0.184970476929002"/>
      <inertia ixx="0.000205386861135714" ixy="1.35715925983726E-09" ixz="1.49085081540378E-06" iyy="0.000509205477303028" iyz="3.50510958146671E-11" izz="0.000701644432736427"/>
    </inertial>
    <visual>
      <origin rpy="0 0 0" xyz="0 0 0"/>
      <geometry>
        <mesh filename="file://$(find armpi_ultra_description)/meshes//base_link.STL"/>
      </geometry>
      <material name="">
        <color rgba="0.792156862745098 0.819607843137255 0.933333333333333 1"/>
      </material>
    </visual>
    <collision>
      <origin rpy="0 0 0" xyz="0 0 0"/>
      <geometry>
        <mesh filename="file://$(find armpi_ultra_description)/meshes/base_link.STL"/>
      </geometry>
    </collision>
  </link>
  <link name="link1">
    <inertial>
      <origin rpy="0 0 0" xyz="0.00183675236262922 -0.00123349114372519 0.00540684297500725"/>
      <mass value="0.0495968437276972"/>
      <inertia ixx="2.12676208903481E-05" ixy="2.80399953258454E-09" ixz="1.31538362697273E-07" iyy="2.36267712831251E-05" iyz="1.30795197761443E-07" izz="4.23603771205122E-05"/>
    </inertial>
    <visual>
      <origin rpy="0 0 0" xyz="0 0 0"/>
      <geometry>
        <mesh filename="file://$(find armpi_ultra_description)/meshes/link1.STL"/>
      </geometry>
      <material name="">
        <color rgba="0.792156862745098 0.819607843137255 0.933333333333333 1"/>
      </material>
    </visual>
    <collision>
      <origin rpy="0 0 0" xyz="0 0 0"/>
      <geometry>
        <mesh filename="file://$(find armpi_ultra_description)/meshes/link1.STL"/>
      </geometry>
    </collision>
  </link>
  <joint name="joint1" type="revolute">
    <origin rpy="0.0069813 0 -0.00032872" xyz="0.066956 -8.1218E-05 0.071005"/>
    <parent link="base_link"/>
    <child link="link1"/>
    <axis xyz="0 0 1"/>
    <limit effort="1000" lower="-2.09" upper="2.09" velocity="10"/>
  </joint>
  <link name="link2">
    <inertial>
      <origin rpy="0 0 0" xyz="-8.1462418107997E-05 -0.0248959972917442 0.0530600779541552"/>
      <mass value="0.0256562517599134"/>
      <inertia ixx="1.11930874674043E-05" ixy="1.79466478804434E-09" ixz="4.31666137254955E-09" iyy="5.73918830225786E-06" iyz="1.80152801844581E-08" izz="8.3166482696753E-06"/>
    </inertial>
    <visual>
      <origin rpy="0 0 0" xyz="0 0 0"/>
      <geometry>
        <mesh filename="file://$(find armpi_ultra_description)/meshes/link2.STL"/>
      </geometry>
      <material name="">
        <color rgba="0.792156862745098 0.819607843137255 0.933333333333333 1"/>
      </material>
    </visual>
    <collision>
      <origin rpy="0 0 0" xyz="0 0 0"/>
      <geometry>
        <mesh filename="file://$(find armpi_ultra_description)/meshes/link2.STL"/>
      </geometry>
    </collision>
  </link>
  <joint name="joint2" type="revolute">
    <origin rpy="0 0 0" xyz="0.0091468 0.025662 0.015922"/>
    <parent link="link1"/>
    <child link="link2"/>
    <axis xyz="-0.0010551 -0.99998 0.0068419"/>
    <limit effort="1000" lower="-2.09" upper="2.09" velocity="10"/>
  </joint>
  <link name="link3">
    <inertial>
      <origin rpy="0 0 0" xyz="1.11245115429898E-06 -0.0171534250124011 0.0473775325062425"/>
      <mass value="0.0539832963097135"/>
      <inertia ixx="9.16651733379202E-06" ixy="-1.43916290848519E-10" ixz="1.26376692708086E-09" iyy="1.02762907567637E-05" iyz="-1.51724247205094E-09" izz="3.54425807511496E-06"/>
    </inertial>
    <visual>
      <origin rpy="0 0 0" xyz="0 0 0"/>
      <geometry>
        <mesh filename="file://$(find armpi_ultra_description)/meshes/link3.STL"/>
      </geometry>
      <material name="">
        <color rgba="0.792156862745098 0.819607843137255 0.933333333333333 1"/>
      </material>
    </visual>
    <collision>
      <origin rpy="0 0 0" xyz="0 0 0"/>
      <geometry>
        <mesh filename="file://$(find armpi_ultra_description)/meshes/link3.STL"/>
      </geometry>
    </collision>
  </link>
  <joint name="joint3" type="revolute">
    <origin rpy="-0.0067561 0.021887 0.0001759" xyz="-0.00022615 -0.0058452 0.10056"/>
    <parent link="link2"/>
    <child link="link3"/>
    <axis xyz="0.000275 -1 -0.00032517"/>
    <limit effort="1000" lower="-2.09" upper="2.09" velocity="10"/>
  </joint>
  <link name="link4">
    <inertial>
      <origin rpy="0 0 0" xyz="0.00395752511921098 -0.0195117566665206 0.0288166015169327"/>
      <mass value="0.0147032550628154"/>
      <inertia ixx="5.01387351753199E-06" ixy="-6.96359548521019E-09" ixz="-1.62523606651003E-07" iyy="3.89035590956844E-06" iyz="4.81048010932894E-09" izz="4.02580541552986E-06"/>
    </inertial>
    <visual>
      <origin rpy="0 0 0" xyz="0 0 0"/>
      <geometry>
        <mesh filename="file://$(find armpi_ultra_description)/meshes/link4.STL"/>
      </geometry>
      <material name="">
        <color rgba="0.792156862745098 0.819607843137255 0.933333333333333 1"/>
      </material>
    </visual>
    <collision>
      <origin rpy="0 0 0" xyz="0 0 0"/>
      <geometry>
        <mesh filename="file://$(find armpi_ultra_description)/meshes/link4.STL"/>
      </geometry>
    </collision>
  </link>
  <joint name="joint4" type="revolute">
    <origin rpy="-0.00022696 -0.0072612 0" xyz="-1.6458E-05 1.6766E-05 0.094708"/>
    <parent link="link3"/>
    <child link="link4"/>
    <axis xyz="0.00040702 -1 -0.000213"/>
    <limit effort="1000" lower="-2.09" upper="2.09" velocity="10"/>
  </joint>
  <link name="link5">
    <inertial>
      <origin rpy="0 0 0" xyz="-0.00012485429546084 5.63304909438861E-06 -0.0018618100016024"/>
      <mass value="0.00208534513323067"/>
      <inertia ixx="1.04715114419907E-07" ixy="-5.69033915905237E-12" ixz="7.6657305072005E-10" iyy="1.07236443877487E-07" iyz="-3.02203220598807E-10" izz="2.06733595380769E-07"/>
    </inertial>
    <visual>
      <origin rpy="0 0 0" xyz="0 0 0"/>
      <geometry>
        <mesh filename="file://$(find armpi_ultra_description)/meshes/link5.STL"/>
      </geometry>
      <material name="">
        <color rgba="0.792156862745098 0.819607843137255 0.933333333333333 1"/>
      </material>
    </visual>
    <collision>
      <origin rpy="0 0 0" xyz="0 0 0"/>
      <geometry>
        <mesh filename="file://$(find armpi_ultra_description)/meshes/link5.STL"/>
      </geometry>
    </collision>
  </link>
  <joint name="joint5" type="revolute">
    <origin rpy="-0.003038 -0.011203 0" xyz="2.3581E-05 -0.0192 0.056107"/>
    <parent link="link4"/>
    <child link="link5"/>
    <axis xyz="-0.012028 0.0031146 -0.99992"/>
    <limit effort="1000" lower="-2.09" upper="2.09" velocity="10"/>
  </joint>
  <link
    name="gripper_link">
    <inertial>
      <origin
        xyz="0.0145481835889059 -0.00315257290321308 0.0253492053712461"
        rpy="0 0 0" />
      <mass
        value="0.0174988490314194" />
      <inertia
        ixx="4.12615692688456E-06"
        ixy="-2.75102939068049E-08"
        ixz="-7.61180742281118E-09"
        iyy="1.57023365316943E-06"
        iyz="2.2563082379695E-08"
        izz="3.2612101868791E-06" />
    </inertial>
    <visual>
      <origin
        xyz="0 0 0"
        rpy="0 0 0" />
      <geometry>
        <mesh
          filename="file://$(find armpi_ultra_description)/meshes/gripper_link.STL" />
      </geometry>
        <material name="">
            <color rgba="0.792156862745098 0.819607843137255 0.933333333333333 1"/>
      </material>
    </visual>
    <collision>
      <origin
        xyz="0 0 0"
        rpy="0 0 0" />
      <geometry>
        <mesh
          filename="file://$(find armpi_ultra_description)/meshes/gripper_link_collision.stl" />
      </geometry>
    </collision>
  </link>
  <joint
    name="gripper_joint"
    type="fixed">
    <origin
      xyz="0 0 0.0054388"
      rpy="0 0 0" />
    <parent
      link="link5" />
    <child
      link="gripper_link" />
    <axis
      xyz="0 0 0" />
  </joint>

  <!-- end effector link -->
  <link name="end_effector_link" />

  <joint name="end_effector_joint" type="fixed">
    <origin xyz="0 0 0.08" rpy="0 0 0"/>
    <parent link="link5"/>
    <child link="end_effector_link"/>
  </joint>
  <link name="camera_connet_link">
    <inertial>
      <origin rpy="0 0 0" xyz="0.0118021523166905 -0.000540782293006269 0.00995705328357074"/>
      <mass value="0.00963635510803445"/>
      <inertia ixx="5.98204756678922E-06" ixy="6.68535029808548E-09" ixz="6.84156124804658E-10" iyy="6.63705685577627E-07" iyz="6.54661287243733E-10" izz="5.67360868792555E-06"/>
    </inertial>
    <visual>
      <origin rpy="0 0 0" xyz="0 0 0"/>
      <geometry>
        <mesh filename="file://$(find armpi_ultra_description)/meshes/camera_connet_link.STL"/>
      </geometry>
      <material name="">
        <color rgba="0.792156862745098 0.819607843137255 0.933333333333333 1"/>
      </material>
    </visual>
    <collision>
      <origin rpy="0 0 0" xyz="0 0 0"/>
      <geometry>
        <mesh filename="file://$(find armpi_ultra_description)/meshes/camera_connet_link.STL"/>
      </geometry>
    </collision>
  </link>
  <joint name="camera_connet_joint" type="fixed">
    <origin rpy="0 -1.5614 0" xyz="-0.040352 -0.019122 0.048005"/>
    <parent link="link4"/>
    <child link="camera_connet_link"/>
    <axis xyz="0 0 0"/>
  </joint>
  <xacro:include filename="$(find armpi_ultra_description)/urdf/gripper.urdf.xacro"/>  
</robot>

